Workbook

Sheet ABC_менеджеры_сумма
G1: X | H1: Y1 | J1: Xa-bc | K1: Ya-bc | M1: Перпендикуляры
G2: 0 | H2: 0 | J2: 0.2 | K2: 0.84337528
G3: 1 | H3: 1 | J3: 0.2 | K3: 0
G5: X | H5: Y2 | J5: Xb-c | K5: Yb-c
G6: 0.2 | H6: 0.84337528 | J6: 0.5 | K6: 0.96076269
G7: 1 | H7: 1 | J7: =J6 -> 0.5 | K7: 0
D21: 20/30/50 | E21: 80/15/5
A22: Названия строк | B22: Сумма по полю Сумма сделки | C22: Номер | D22: X | E22: Y0 | F22: Y1 | G22: Y0-Y1 | H22: Y2 | I22: Y0-Y2 | J22: ABC
A23: Яковлев Артем Игоревич | B23: 0.48691357 | C23: 1 | D23: =C23/MAX(C:C) -> 0.05 | E23: =B23 -> 0.48691357 | F23: =D23 -> 0.05 | G23: =E23-F23 -> 0.43691357 | H23: =0.1958*D23+0.8042 -> 0.81399 | I23: =E23-H23 -> -0.32707643 | J23: A
A24: Фролов Сергей Викторович | B24: 0.67919953 | C24: 2 | D24: =C24/MAX(C:C) -> 0.1 | E24: =B24 -> 0.67919953 | F24: =D24 -> 0.1 | G24: =E24-F24 -> 0.57919953 | H24: =0.1958*D24+0.8042 -> 0.82378 | I24: =E24-H24 -> -0.14458047 | J24: A
A25: Иванова Анна Сергеевна | B25: 0.78511604 | C25: 3 | D25: =C25/MAX(C:C) -> 0.15 | E25: =B25 -> 0.78511604 | F25: =D25 -> 0.15 | G25: =E25-F25 -> 0.63511604 | H25: =0.1958*D25+0.8042 -> 0.83357 | I25: =E25-H25 -> -0.048453962 | J25: A
A26: Ткаченко Андрей Олегович | B26: 0.84337528 | C26: 4 | D26: =C26/MAX(C:C) -> 0.2 | E26: =B26 -> 0.84337528 | F26: =D26 -> 0.2 | G26: =E26-F26 -> 0.64337528 | H26: =0.1958*D26+0.8042 -> 0.84336 | I26: =E26-H26 -> 1.5284493e-05 | J26: A
A27: Семенова Ирина Валерьевна | B27: 0.87932818 | C27: 5 | D27: =C27/MAX(C:C) -> 0.25 | E27: =B27 -> 0.87932818 | F27: =D27 -> 0.25 | G27: =E27-F27 -> 0.62932818 | H27: =0.1958*D27+0.8042 -> 0.85315 | I27: =E27-H27 -> 0.026178185 | J27: B
A28: Орлов Павел Денисович | B28: 0.90468106 | C28: 6 | D28: =C28/MAX(C:C) -> 0.3 | E28: =B28 -> 0.90468106 | F28: =D28 -> 0.3 | G28: =E28-F28 -> 0.60468106 | H28: =0.1958*D28+0.8042 -> 0.86294 | I28: =E28-H28 -> 0.041741064 | J28: B
A29: Кузнецов Максим Алексеевич | B29: 0.92303698 | C29: 7 | D29: =C29/MAX(C:C) -> 0.35 | E29: =B29 -> 0.92303698 | F29: =D29 -> 0.35 | G29: =E29-F29 -> 0.57303698 | H29: =0.1958*D29+0.8042 -> 0.87273 | I29: =E29-H29 -> 0.050306981 | J29: B
A30: Морозова Елена Андреевна | B30: 0.93959614 | C30: 8 | D30: =C30/MAX(C:C) -> 0.4 | E30: =B30 -> 0.93959614 | F30: =D30 -> 0.4 | G30: =E30-F30 -> 0.53959614 | H30: =0.1958*D30+0.8042 -> 0.88252 | I30: =E30-H30 -> 0.057076137 | J30: B
A31: Волков Дмитрий Романович | B31: 0.95049056 | C31: 9 | D31: =C31/MAX(C:C) -> 0.45 | E31: =B31 -> 0.95049056 | F31: =D31 -> 0.45 | G31: =E31-F31 -> 0.50049056 | H31: =0.1958*D31+0.8042 -> 0.89231 | I31: =E31-H31 -> 0.058180557 | J31: B
A32: Соколова Мария Ильинична | B32: 0.96076269 | C32: 10 | D32: =C32/MAX(C:C) -> 0.5 | E32: =B32 -> 0.96076269 | F32: =D32 -> 0.5 | G32: =E32-F32 -> 0.46076269 | H32: =0.1958*D32+0.8042 -> 0.9021 | I32: =E32-H32 -> 0.058662693 | J32: C
A33: Лебедев Николай Олегович | B33: 0.96953441 | C33: 11 | D33: =C33/MAX(C:C) -> 0.55 | E33: =B33 -> 0.96953441 | F33: =D33 -> 0.55 | G33: =E33-F33 -> 0.41953441 | H33: =0.1958*D33+0.8042 -> 0.91189 | I33: =E33-H33 -> 0.057644408 | J33: C
A34: Новикова Ольга Викторовна | B34: 0.97720022 | C34: 12 | D34: =C34/MAX(C:C) -> 0.6 | E34: =B34 -> 0.97720022 | F34: =D34 -> 0.6 | G34: =E34-F34 -> 0.37720022 | H34: =0.1958*D34+0.8042 -> 0.92168 | I34: =E34-H34 -> 0.055520219 | J34: C
... A42: Михайлова Алина Романовна | B42: 1 | C42: 20 | D42: =C42/MAX(C:C) -> 1 | E42: =B42 -> 1 | F42: =D42 -> 1 | G42: =E42-F42 -> 0 | H42: =0.1958*D42+0.8042 -> 1 | I42: =E42-H42 -> 0 | J42: C

Sheet ABC_Менеджеры_сделки
G1: X | H1: Y1 | J1: Xa-bc | K1: Ya-bc | M1: Перпендикуляры
G2: 0 | H2: 0 | J2: 0.25 | K2: 0.74759015
G3: 1 | H3: 1 | J3: =J2 -> 0.25 | K3: 0
G5: X | H5: Y2 | J5: Xb-c | K5: Yb-c
G6: 0.25 | H6: 0.74759015 | J6: 0.6 | K6: 0.94537665
G7: 1 | H7: 1 | J7: =J6 -> 0.6 | K7: 0
D21: 20/30/50 | E21: 80/15/5
A22: Названия строк | B22: Количество по полю ФИО менеджера | C22: Номер | D22: X | E22: Y0 | F22: Y1 | G22: Y0-Y1 | H22: Y2 | I22: Y0-Y2 | J22: ABC
A23: Яковлев Артем Игоревич | B23: 0.35273117 | C23: 1 | D23: =C23/MAX(C:C) -> 0.05 | E23: =B23 -> 0.35273117 | F23: =D23 -> 0.05 | G23: =E23-F23 -> 0.30273117 | H23: =0.3365*D23+0.6635 -> 0.680325 | I23: =E23-H23 -> -0.32759383 | J23: А
A24: Фролов Сергей Викторович | B24: 0.52195644 | C24: 2 | D24: =C24/MAX(C:C) -> 0.1 | E24: =B24 -> 0.52195644 | F24: =D24 -> 0.1 | G24: =E24-F24 -> 0.42195644 | H24: =0.3365*D24+0.6635 -> 0.69715 | I24: =E24-H24 -> -0.17519356 | J24: А
A25: Иванова Анна Сергеевна | B25: 0.62227776 | C25: 3 | D25: =C25/MAX(C:C) -> 0.15 | E25: =B25 -> 0.62227776 | F25: =D25 -> 0.15 | G25: =E25-F25 -> 0.47227776 | H25: =0.3365*D25+0.6635 -> 0.713975 | I25: =E25-H25 -> -0.091697242 | J25: А
A26: Ткаченко Андрей Олегович | B26: 0.69368083 | C26: 4 | D26: =C26/MAX(C:C) -> 0.2 | E26: =B26 -> 0.69368083 | F26: =D26 -> 0.2 | G26: =E26-F26 -> 0.49368083 | H26: =0.3365*D26+0.6635 -> 0.7308 | I26: =E26-H26 -> -0.037119172 | J26: А
A27: Семенова Ирина Валерьевна | B27: 0.74759015 | C27: 5 | D27: =C27/MAX(C:C) -> 0.25 | E27: =B27 -> 0.74759015 | F27: =D27 -> 0.25 | G27: =E27-F27 -> 0.49759015 | H27: =0.3365*D27+0.6635 -> 0.747625 | I27: =E27-H27 -> -3.4853624e-05 | J27: B
A28: Орлов Павел Денисович | B28: 0.79114602 | C28: 6 | D28: =C28/MAX(C:C) -> 0.3 | E28: =B28 -> 0.79114602 | F28: =D28 -> 0.3 | G28: =E28-F28 -> 0.49114602 | H28: =0.3365*D28+0.6635 -> 0.76445 | I28: =E28-H28 -> 0.026696019 | J28: B
A29: Кузнецов Максим Алексеевич | B29: 0.82684755 | C29: 7 | D29: =C29/MAX(C:C) -> 0.35 | E29: =B29 -> 0.82684755 | F29: =D29 -> 0.35 | G29: =E29-F29 -> 0.47684755 | H29: =0.3365*D29+0.6635 -> 0.781275 | I29: =E29-H29 -> 0.045572554 | J29: B
A30: Морозова Елена Андреевна | B30: 0.85969297 | C30: 8 | D30: =C30/MAX(C:C) -> 0.4 | E30: =B30 -> 0.85969297 | F30: =D30 -> 0.4 | G30: =E30-F30 -> 0.45969297 | H30: =0.3365*D30+0.6635 -> 0.7981 | I30: =E30-H30 -> 0.061592967 | J30: B
A31: Волков Дмитрий Романович | B31: 0.88504106 | C31: 9 | D31: =C31/MAX(C:C) -> 0.45 | E31: =B31 -> 0.88504106 | F31: =D31 -> 0.45 | G31: =E31-F31 -> 0.43504106 | H31: =0.3365*D31+0.6635 -> 0.814925 | I31: =E31-H31 -> 0.070116057 | J31: B
A32: Соколова Мария Ильинична | B32: 0.90717601 | C32: 10 | D32: =C32/MAX(C:C) -> 0.5 | E32: =B32 -> 0.90717601 | F32: =D32 -> 0.5 | G32: =E32-F32 -> 0.40717601 | H32: =0.3365*D32+0.6635 -> 0.83175 | I32: =E32-H32 -> 0.075426009 | J32: С
A33: Лебедев Николай Олегович | B33: 0.92752588 | C33: 11 | D33: =C33/MAX(C:C) -> 0.55 | E33: =B33 -> 0.92752588 | F33: =D33 -> 0.55 | G33: =E33-F33 -> 0.37752588 | H33: =0.3365*D33+0.6635 -> 0.848575 | I33: =E33-H33 -> 0.078950884 | J33: С
A34: Новикова Ольга Викторовна | B34: 0.94537665 | C34: 12 | D34: =C34/MAX(C:C) -> 0.6 | E34: =B34 -> 0.94537665 | F34: =D34 -> 0.6 | G34: =E34-F34 -> 0.34537665 | H34: =0.3365*D34+0.6635 -> 0.8654 | I34: =E34-H34 -> 0.079976651 | J34: С
... A42: Егоров Илья Александрович | B42: 1 | C42: 20 | D42: =C42/MAX(C:C) -> 1 | E42: =B42 -> 1 | F42: =D42 -> 1 | G42: =E42-F42 -> 0 | H42: =0.3365*D42+0.6635 -> 1 | I42: =E42-H42 -> 0 | J42: С

Sheet Данные
A1: ФИО менеджера | B1: ФИО клиента | C1: Дата сделки | D1: Сумма сделки
A2: Кузнецов Максим Алексеевич | B2: Сидорова Полина Михайловна | C2: 46023 | D2: 5200
A3: Новикова Ольга Викторовна | B3: Степанов Михаил Олегович | C3: 46023 | D3: 9754
A4: Ткаченко Андрей Олегович | B4: Борисов Борис Александрович | C4: 46023 | D4: 24121
A5: Ткаченко Андрей Олегович | B5: Смирнова Мария Викторовна | C5: 46023 | D5: 33813
A6: Фролов Сергей Викторович | B6: Андреев Федор Ильич | C6: 46023 | D6: 38499
A7: Фролов Сергей Викторович | B7: Куликов Вадим Кириллович | C7: 46023 | D7: 25319
A8: Фролов Сергей Викторович | B8: Федорова Александра Олеговна | C8: 46023 | D8: 37158
A9: Яковлев Артем Игоревич | B9: Баранова Ольга Евгеньевна | C9: 46023 | D9: 30144
A10: Яковлев Артем Игоревич | B10: Васильев Олег Федорович | C10: 46023 | D10: 63366
A11: Яковлев Артем Игоревич | B11: Семенова Екатерина Алексеевна | C11: 46023 | D11: 42753
A12: Яковлев Артем Игоревич | B12: Соколова Елена Владимировна | C12: 46023 | D12: 45643
A13: Яковлев Артем Игоревич | B13: Степанов Юрий Николаевич | C13: 46023 | D13: 33452
... A2802: Яковлев Артем Игоревич | B2802: Семенова Екатерина Алексеевна | C2802: 46265 | D2802: 47660

Sheet ABC Менеджеры
B7: ФИО Менеджера (по алфавиту) | C7: ABC по сумме сделки | D7: ABC по количеству сделок
A8: 1 | B8: Васильева Дарья Павловна | C8: =VLOOKUP(B8,ABC_менеджеры_сумма!$A$23:$J$42,10,0) -> C | D8: =VLOOKUP(B8,ABC_Менеджеры_сделки!$A$23:$J$42,10,0) -> С
A9: 2 | B9: Волков Дмитрий Романович | C9: =VLOOKUP(B9,ABC_менеджеры_сумма!$A$23:$J$42,10,0) -> B | D9: =VLOOKUP(B9,ABC_Менеджеры_сделки!$A$23:$J$42,10,0) -> B
A10: 3 | B10: Егоров Илья Александрович | C10: =VLOOKUP(B10,ABC_менеджеры_сумма!$A$23:$J$42,10,0) -> C | D10: =VLOOKUP(B10,ABC_Менеджеры_сделки!$A$23:$J$42,10,0) -> С
A11: 4 | B11: Иванова Анна Сергеевна | C11: =VLOOKUP(B11,ABC_менеджеры_сумма!$A$23:$J$42,10,0) -> A | D11: =VLOOKUP(B11,ABC_Менеджеры_сделки!$A$23:$J$42,10,0) -> А
A12: 5 | B12: Козлов Алексей Михайлович | C12: =VLOOKUP(B12,ABC_менеджеры_сумма!$A$23:$J$42,10,0) -> C | D12: =VLOOKUP(B12,ABC_Менеджеры_сделки!$A$23:$J$42,10,0) -> С
A13: 6 | B13: Кузнецов Максим Алексеевич | C13: =VLOOKUP(B13,ABC_менеджеры_сумма!$A$23:$J$42,10,0) -> B | D13: =VLOOKUP(B13,ABC_Менеджеры_сделки!$A$23:$J$42,10,0) -> B
A14: 7 | B14: Лебедев Николай Олегович | C14: =VLOOKUP(B14,ABC_менеджеры_сумма!$A$23:$J$42,10,0) -> C | D14: =VLOOKUP(B14,ABC_Менеджеры_сделки!$A$23:$J$42,10,0) -> С
A15: 8 | B15: Михайлова Алина Романовна | C15: =VLOOKUP(B15,ABC_менеджеры_сумма!$A$23:$J$42,10,0) -> C | D15: =VLOOKUP(B15,ABC_Менеджеры_сделки!$A$23:$J$42,10,0) -> С
A16: 9 | B16: Морозова Елена Андреевна | C16: =VLOOKUP(B16,ABC_менеджеры_сумма!$A$23:$J$42,10,0) -> B | D16: =VLOOKUP(B16,ABC_Менеджеры_сделки!$A$23:$J$42,10,0) -> B
A17: 10 | B17: Новикова Ольга Викторовна | C17: =VLOOKUP(B17,ABC_менеджеры_сумма!$A$23:$J$42,10,0) -> C | D17: =VLOOKUP(B17,ABC_Менеджеры_сделки!$A$23:$J$42,10,0) -> С
A18: 11 | B18: Орлов Павел Денисович | C18: =VLOOKUP(B18,ABC_менеджеры_сумма!$A$23:$J$42,10,0) -> B | D18: =VLOOKUP(B18,ABC_Менеджеры_сделки!$A$23:$J$42,10,0) -> B
A19: 12 | B19: Павлова Татьяна Сергеевна | C19: =VLOOKUP(B19,ABC_менеджеры_сумма!$A$23:$J$42,10,0) -> C | D19: =VLOOKUP(B19,ABC_Менеджеры_сделки!$A$23:$J$42,10,0) -> С
... A27: 20 | B27: Яковлев Артем Игоревич | C27: =VLOOKUP(B27,ABC_менеджеры_сумма!$A$23:$J$42,10,0) -> A | D27: =VLOOKUP(B27,ABC_Менеджеры_сделки!$A$23:$J$42,10,0) -> А

Sheet ABC_XYZ Клиенты
A1: Названия строк | B1: Сумма по полю Сумма сделки | C1: ABC | F1: Клиент | G1: Вариация | H1: ABC | I1: XYZ | J1: Сумма | R1: ФИО Клиента (все клиенты) | S1: янв | T1: фев | U1: мар | V1: апр | W1: май | X1: июн | Y1: июл | Z1: авг | AA1: ABC | AB1: XYZ | AD1: Сумма по полю Сумма | AE1: Названия столбцов
A2: Алексеев Андрей Александрович | B2: 144110 | C2: =VLOOKUP(B2,$N$34:$O$36,2,1) -> C | F2: Соколова Елена Владимировна | G2: 0.032647562 | H2: A | I2: X | J2: 1281153 | R2: Захаров Павел Артемович | S2: 234052 | T2: 216077 | U2: 241027 | V2: 28462 | W2: 54340 | X2: 193296 | Y2: 229566 | Z2: 233044 | AA2: A | AB2: Z | AD2: Названия строк | AE2: X | AF2: Y | AG2: Z
A3: Алексеев Илья Дмитриевич | B3: 108060 | C3: =VLOOKUP(B3,$N$34:$O$36,2,1) -> C | F3: Кузнецов Никита Антонович | G3: 0.032044011 | H3: A | I3: X | J3: 962043 | R3: Орлова Валерия Олеговна | S3: 183801 | T3: 184120 | U3: 179863 | V3: 170425 | W3: 173716 | X3: 169770 | Y3: 183172 | Z3: 181646 | AA3: A | AB3: Z | AD3: A | AE3: 27536105 | AF3: 19443417 | AG3: 18864255
A4: Алексеева Ксения Алексеевна | B4: 96257 | C4: =VLOOKUP(B4,$N$34:$O$36,2,1) -> C | F4: Комаров Степан Федорович | G4: 0.02996864 | H4: A | I4: X | J4: 223066 | R4: Новикова Екатерина Ивановна | S4: 116467 | T4: 208399 | U4: 264694 | V4: 213152 | W4: 283059 | X4: 120640 | Y4: 103649 | Z4: 98881 | AA4: A | AB4: Z | AD4: B | AE4: 4907912 | AF4: 3755298 | AG4: 3769492
A5: Алексеева Полина Евгеньевна | B5: 91763 | C5: =VLOOKUP(B5,$N$34:$O$36,2,1) -> C | F5: Баранова Ольга Евгеньевна | G5: 0.027595462 | H5: A | I5: X | J5: 796801 | R5: Петров Николай Александрович | S5: 169665 | T5: 160532 | U5: 173415 | V5: 174376 | W5: 174568 | X5: 161080 | Y5: 166550 | Z5: 169274 | AA5: A | AB5: Z | AD5: C | AE5: 1877262 | AF5: 1057776 | AG5: 1210679
A6: Андреев Андрей Игоревич | B6: 159395 | C6: =VLOOKUP(B6,$N$34:$O$36,2,1) -> C | F6: Васильев Александр Игоревич | G6: 0.027508303 | H6: A | I6: X | J6: 743301 | R6: Михайлов Юрий Павлович | S6: 178222 | T6: 150966 | U6: 182303 | V6: 130158 | W6: 197803 | X6: 178110 | Y6: 124476 | Z6: 177636 | AA6: A | AB6: Y
A7: Андреев Владимир Денисович | B7: 89558 | C7: =VLOOKUP(B7,$N$34:$O$36,2,1) -> C | F7: Комарова Людмила Сергеевна | G7: 0.02669044 | H7: A | I7: X | J7: 474039 | R7: Григорьева Марина Антоновна | S7: 151209 | T7: 155598 | U7: 172682 | V7: 161027 | W7: 151203 | X7: 158179 | Y7: 180762 | Z7: 125537 | AA7: A | AB7: Y
A8: Андреев Федор Ильич | B8: 488621 | C8: =VLOOKUP(B8,$N$34:$O$36,2,1) -> C | F8: Баранов Антон Александрович | G8: 0.026474541 | H8: A | I8: X | J8: 323488 | R8: Степанов Алексей Александрович | S8: 176330 | T8: 121210 | U8: 152724 | V8: 160583 | W8: 150051 | X8: 137644 | Y8: 170553 | Z8: 161697 | AA8: A | AB8: Z
A9: Андреева Ольга Олеговна | B9: 681247 | C9: =VLOOKUP(B9,$N$34:$O$36,2,1) -> C | F9: Волкова Юлия Викторовна | G9: 0.026103982 | H9: A | I9: X | J9: 869292 | R9: Козлов Максим Антонович | S9: 151188 | T9: 150633 | U9: 160966 | V9: 152034 | W9: 161256 | X9: 147233 | Y9: 148502 | Z9: 151988 | AA9: B | AB9: Z
A10: Андреева Полина Ильинична | B10: 147620 | C10: =VLOOKUP(B10,$N$34:$O$36,2,1) -> C | F10: Борисова Ксения Николаевна | G10: 0.02604524 | H10: A | I10: X | J10: 256396 | R10: Белов Юрий Максимович | S10: 286775 | T10: 221110 | U10: 38080 | V10: 47894 | W10: 59927 | X10: 119964 | Y10: 251860 | Z10: 195841 | AA10: B | AB10: Z
A11: Андреева Светлана Ильинична | B11: 188072 | C11: =VLOOKUP(B11,$N$34:$O$36,2,1) -> C | F11: Иванов Михаил Дмитриевич | G11: 0.026021245 | H11: A | I11: X | J11: 632970 | R11: Степанова Ольга Денисовна | S11: 206692 | T11: 230270 | U11: 231500 | V11: 173326 | W11: 27445 | X11: 202914 | Y11: 53448 | Z11: 50577 | AA11: B | AB11: X
A12: Баранов Антон Александрович | B12: 323488 | C12: =VLOOKUP(B12,$N$34:$O$36,2,1) -> C | F12: Сидорова Екатерина Денисовна | G12: 0.025665553 | H12: A | I12: X | J12: 473530
A13: Баранов Виктор Антонович | B13: 132305 | C13: =VLOOKUP(B13,$N$34:$O$36,2,1) -> C | F13: Николаева Софья Игоревна | G13: 0.025554328 | H13: A | I13: X | J13: 1232944
A14: Баранов Евгений Борисович | B14: 1332843 | C14: =VLOOKUP(B14,$N$34:$O$36,2,1) -> C | F14: Лебедев Павел Артемович | G14: 0.02502542 | H14: A | I14: X | J14: 1000118 | M14: Сводная таблица
A15: Баранов Роман Артемович | B15: 219816 | C15: =VLOOKUP(B15,$N$34:$O$36,2,1) -> C | F15: Иванов Юрий Дмитриевич | G15: 0.02439108 | H15: A | I15: X | J15: 258435 | M15: количество клиентов каждой категории
A16: Баранова Ольга Евгеньевна | B16: 796801 | C16: =VLOOKUP(B16,$N$34:$O$36,2,1) -> C | F16: Зайцев Степан Олегович | G16: 0.024181571 | H16: A | I16: X | J16: 519961 | N16: X | O16: Y | P16: Z
A17: Белов Вадим Викторович | B17: 112199 | C17: =VLOOKUP(B17,$N$34:$O$36,2,1) -> C | F17: Романов Кирилл Дмитриевич | G17: 0.024066534 | H17: A | I17: X | J17: 289112 | M17: A | N17: 45 | O17: 33 | P17: 31
A18: Белов Евгений Дмитриевич | B18: 212122 | C18: =VLOOKUP(B18,$N$34:$O$36,2,1) -> C | F18: Белов Степан Дмитриевич | G18: 0.024026638 | H18: A | I18: X | J18: 247989 | M18: B | N18: 33 | O18: 26 | P18: 26
A19: Белов Степан Артемович | B19: 180288 | C19: =VLOOKUP(B19,$N$34:$O$36,2,1) -> C | F19: Яковлева Валерия Николаевна | G19: 0.023935477 | H19: A | I19: X | J19: 272595 | M19: C | N19: 19 | O19: 11 | P19: 13
A20: Белов Степан Дмитриевич | B20: 247989 | C20: =VLOOKUP(B20,$N$34:$O$36,2,1) -> C | F20: Андреева Ольга Олеговна | G20: 0.023475073 | H20: A | I20: X | J20: 681247
A21: Борисов Борис Александрович | B21: 196129 | C21: =VLOOKUP(B21,$N$34:$O$36,2,1) -> C | F21: Козлова Надежда Игоревна | G21: 0.023208985 | H21: A | I21: X | J21: 370056 | M21: Сумма сделок в каждой категории
A22: Борисов Вадим Артемович | B22: 87299 | C22: =VLOOKUP(B22,$N$34:$O$36,2,1) -> C | F22: Куликов Вадим Кириллович | G22: 0.023057442 | H22: A | I22: X | J22: 396689 | N22: X | O22: Y | P22: Z
A23: Борисов Игорь Евгеньевич | B23: 476581 | C23: =VLOOKUP(B23,$N$34:$O$36,2,1) -> C | F23: Кузнецов Павел Андреевич | G23: 0.022728149 | H23: A | I23: X | J23: 496400 | M23: A | N23: 27536105 | O23: 19443417 | P23: 18864255
A24: Борисова Анастасия Александровна | B24: 101723 | C24: =VLOOKUP(B24,$N$34:$O$36,2,1) -> C | F24: Петров Николай Олегович | G24: 0.022416918 | H24: A | I24: X | J24: 676272 | M24: B | N24: 4907912 | O24: 3755298 | P24: 3769492
A25: Борисова Ксения Николаевна | B25: 256396 | C25: =VLOOKUP(B25,$N$34:$O$36,2,1) -> C | F25: Новикова Екатерина Федоровна | G25: 0.0223675 | H25: A | I25: X | J25: 247879 | M25: C | N25: 1877262 | O25: 1057776 | P25: 1210679
A26: Борисова Татьяна Максимовна | B26: 172013 | C26: =VLOOKUP(B26,$N$34:$O$36,2,1) -> C | F26: Романова Виктория Дмитриевна | G26: 0.02236298 | H26: A | I26: X | J26: 406709
A27: Васильев Александр Игоревич | B27: 743301 | C27: =VLOOKUP(B27,$N$34:$O$36,2,1) -> C | F27: Николаев Иван Борисович | G27: 0.022098189 | H27: A | I27: X | J27: 464356
A28: Васильев Артем Евгеньевич | B28: 446372 | C28: =VLOOKUP(B28,$N$34:$O$36,2,1) -> C | F28: Сидоров Федор Кириллович | G28: 0.022030586 | H28: A | I28: X | J28: 674351
A29: Васильев Илья Антонович | B29: 52915 | C29: =VLOOKUP(B29,$N$34:$O$36,2,1) -> C | F29: Григорьева Анна Денисовна | G29: 0.021794847 | H29: A | I29: X | J29: 315469
A30: Васильев Олег Федорович | B30: 1950239 | C30: =VLOOKUP(B30,$N$34:$O$36,2,1) -> C | F30: Кузнецов Борис Максимович | G30: 0.021744976 | H30: A | I30: X | J30: 1046347 | N30: 0 | O30: X
A31: Васильев Павел Дмитриевич | B31: 110600 | C31: =VLOOKUP(B31,$N$34:$O$36,2,1) -> C | F31: Романов Кирилл Романович | G31: 0.020861286 | H31: A | I31: X | J31: 221902 | N31: 0.1 | O31: Y
A32: Васильева Алина Ивановна | B32: 153941 | C32: =VLOOKUP(B32,$N$34:$O$36,2,1) -> C | F32: Павлова Анастасия Романовна | G32: 0.020801286 | H32: A | I32: X | J32: 1012313 | N32: 0.25 | O32: Z
A33: Волкова Алина Александровна | B33: 1021849 | C33: =VLOOKUP(B33,$N$34:$O$36,2,1) -> C | F33: Сидоров Максим Иванович | G33: 0.020626633 | H33: A | I33: X | J33: 1011121
A34: Волкова Алина Евгеньевна | B34: 401747 | C34: =VLOOKUP(B34,$N$34:$O$36,2,1) -> C | F34: Степанов Кирилл Ильич | G34: 0.020610236 | H34: A | I34: X | J34: 1336720 | N34: 0 | O34: A
A35: Волкова Анна Андреевна | B35: 107523 | C35: =VLOOKUP(B35,$N$34:$O$36,2,1) -> C | F35: Борисов Игорь Евгеньевич | G35: 0.020303803 | H35: A | I35: X | J35: 476581 | N35: 0.8 | O35: B
A36: Волкова Елена Ивановна | B36: 114021 | C36: =VLOOKUP(B36,$N$34:$O$36,2,1) -> C | F36: Баранов Евгений Борисович | G36: 0.020187106 | H36: A | I36: X | J36: 1332843 | N36: 0.95 | O36: C
A37: Волкова Надежда Андреевна | B37: 403440 | C37: =VLOOKUP(B37,$N$34:$O$36,2,1) -> C | F37: Новикова Мария Андреевна | G37: 0.01979881 | H37: A | I37: X | J37: 1076932
A38: Волкова Юлия Викторовна | B38: 869292 | C38: =VLOOKUP(B38,$N$34:$O$36,2,1) -> C | F38: Семенов Борис Павлович | G38: 0.018961019 | H38: A | I38: X | J38: 330631
A39: Волкова Юлия Федоровна | B39: 100294 | C39: =VLOOKUP(B39,$N$34:$O$36,2,1) -> C | F39: Романова Валерия Сергеевна | G39: 0.016997885 | H39: A | I39: X | J39: 1087017
A40: Воробьев Алексей Николаевич | B40: 229598 | C40: =VLOOKUP(B40,$N$34:$O$36,2,1) -> C | F40: Павлова Татьяна Викторовна | G40: 0.016797506 | H40: A | I40: X | J40: 503387
...
